Workbook

Sheet Resumen
A1: Resultados de pruebas - ITMentorSoft
A2: Generado: 2026-10-23 14:56 · Casos: Azure DevOps especializacion-itm / Trabajo de Grado - Tutor inteligente (lectura por MCP) (2026-10-23) · Ejecuciones de Katalon leídas: 34 · Aplicación: https://itmentorsoft.com
A4: Resultado (casos de Azure) | B4: Casos | C4: % del total
A5: Pasó | B5: =COUNTIF(Detalle!$H$2:$H$44,A5) | C5: =IF($B$10=0,0,B5/$B$10)
A6: Falló | B6: =COUNTIF(Detalle!$H$2:$H$44,A6) | C6: =IF($B$10=0,0,B6/$B$10)
A7: Error | B7: =COUNTIF(Detalle!$H$2:$H$44,A7) | C7: =IF($B$10=0,0,B7/$B$10)
A8: No ejecutado | B8: =COUNTIF(Detalle!$H$2:$H$44,A8) | C8: =IF($B$10=0,0,B8/$B$10)
A9: No automatizable | B9: =COUNTIF(Detalle!$H$2:$H$44,A9) | C9: =IF($B$10=0,0,B9/$B$10)
A10: Total | B10: =SUM(B5:B9) | C10: =IF(B10=0,0,B10/B10)
A11: Ejecutados | B11: =B5+B6+B7
A12: % de aprobación (pasó / ejecutados) | B12: =IF(B11=0,0,B5/B11)
A14: Tipo de caso | B14: Casos | C14: Pasó | D14: Falló / Error | E14: Sin ejecutar
A15: Automatizado | B15: =COUNTIF(Detalle!$E$2:$E$44,A15) | C15: =COUNTIFS(Detalle!$E$2:$E$44,A15,Detalle!$H$2:$H$44,"Pasó") | D15: =COUNTIFS(Detalle!$E$2:$E$44,A15,Detalle!$H$2:$H$44,"Falló")+COUNTIFS(Detalle!$E$2:$E$44,A15,Detalle!$H$2:$H$44,"Error") | E15: =B15-C15-D15
A16: Automatizado parcial | B16: =COUNTIF(Detalle!$E$2:$E$44,A16) | C16: =COUNTIFS(Detalle!$E$2:$E$44,A16,Detalle!$H$2:$H$44,"Pasó") | D16: =COUNTIFS(Detalle!$E$2:$E$44,A16,Detalle!$H$2:$H$44,"Falló")+COUNTIFS(Detalle!$E$2:$E$44,A16,Detalle!$H$2:$H$44,"Error") | E16: =B16-C16-D16
A17: No automatizable | B17: =COUNTIF(Detalle!$E$2:$E$44,A17) | C17: =COUNTIFS(Detalle!$E$2:$E$44,A17,Detalle!$H$2:$H$44,"Pasó") | D17: =COUNTIFS(Detalle!$E$2:$E$44,A17,Detalle!$H$2:$H$44,"Falló")+COUNTIFS(Detalle!$E$2:$E$44,A17,Detalle!$H$2:$H$44,"Error") | E17: =B17-C17-D17
A19: Pruebas Katalon | B19: Casos
A20: Pruebas automatizadas | B20: =COUNTA(Casos_Katalon!$A$2:$A$21)
A21: Pasaron | B21: =COUNTIF(Casos_Katalon!$D$2:$D$21,"Pasó")
A22: Fallaron | B22: =COUNTIF(Casos_Katalon!$D$2:$D$21,"Falló")
A23: Error | B23: =COUNTIF(Casos_Katalon!$D$2:$D$21,"Error")
A24: No ejecutadas | B24: =COUNTIF(Casos_Katalon!$D$2:$D$21,"No ejecutado")
A26: HU | B26: Historia de usuario | C26: Casos | D26: Pasó | E26: Falló / Error | F26: Sin ejecutar
A27: 176 | B27: HU 1.1.1 Registro de usuarios | C27: =COUNTIF(HU_Caso!$A$2:$A$44,A27) | D27: =COUNTIFS(HU_Caso!$A$2:$A$44,A27,HU_Caso!$D$2:$D$44,"Pasó") | E27: =COUNTIFS(HU_Caso!$A$2:$A$44,A27,HU_Caso!$D$2:$D$44,"Falló")+COUNTIFS(HU_Caso!$A$2:$A$44,A27,HU_Caso!$D$2:$D$44,"Error") | F27: =C27-D27-E27
A28: 181 | B28: HU 1.1.2 Inicio de sesión | C28: =COUNTIF(HU_Caso!$A$2:$A$44,A28) | D28: =COUNTIFS(HU_Caso!$A$2:$A$44,A28,HU_Caso!$D$2:$D$44,"Pasó") | E28: =COUNTIFS(HU_Caso!$A$2:$A$44,A28,HU_Caso!$D$2:$D$44,"Falló")+COUNTIFS(HU_Caso!$A$2:$A$44,A28,HU_Caso!$D$2:$D$44,"Error") | F28: =C28-D28-E28
A29: 186 | B29: HU 1.1.3 Reestablecer contraseña | C29: =COUNTIF(HU_Caso!$A$2:$A$44,A29) | D29: =COUNTIFS(HU_Caso!$A$2:$A$44,A29,HU_Caso!$D$2:$D$44,"Pasó") | E29: =COUNTIFS(HU_Caso!$A$2:$A$44,A29,HU_Caso!$D$2:$D$44,"Falló")+COUNTIFS(HU_Caso!$A$2:$A$44,A29,HU_Caso!$D$2:$D$44,"Error") | F29: =C29-D29-E29
A30: 193 | B30: HU 1.2.1 Asignación de roles | C30: =COUNTIF(HU_Caso!$A$2:$A$44,A30) | D30: =COUNTIFS(HU_Caso!$A$2:$A$44,A30,HU_Caso!$D$2:$D$44,"Pasó") | E30: =COUNTIFS(HU_Caso!$A$2:$A$44,A30,HU_Caso!$D$2:$D$44,"Falló")+COUNTIFS(HU_Caso!$A$2:$A$44,A30,HU_Caso!$D$2:$D$44,"Error") | F30: =C30-D30-E30
A31: 198 | B31: HU 1.2.2 Acceso y privacidad en datos | C31: =COUNTIF(HU_Caso!$A$2:$A$44,A31) | D31: =COUNTIFS(HU_Caso!$A$2:$A$44,A31,HU_Caso!$D$2:$D$44,"Pasó") | E31: =COUNTIFS(HU_Caso!$A$2:$A$44,A31,HU_Caso!$D$2:$D$44,"Falló")+COUNTIFS(HU_Caso!$A$2:$A$44,A31,HU_Caso!$D$2:$D$44,"Error") | F31: =C31-D31-E31
A32: 203 | B32: HU 1.2.3 Acceso a rubricas de calificación | C32: =COUNTIF(HU_Caso!$A$2:$A$44,A32) | D32: =COUNTIFS(HU_Caso!$A$2:$A$44,A32,HU_Caso!$D$2:$D$44,"Pasó") | E32: =COUNTIFS(HU_Caso!$A$2:$A$44,A32,HU_Caso!$D$2:$D$44,"Falló")+COUNTIFS(HU_Caso!$A$2:$A$44,A32,HU_Caso!$D$2:$D$44,"Error") | F32: =C32-D32-E32
A33: 207 | B33: HU 1.2.4 Reportes de estudiantes | C33: =COUNTIF(HU_Caso!$A$2:$A$44,A33) | D33: =COUNTIFS(HU_Caso!$A$2:$A$44,A33,HU_Caso!$D$2:$D$44,"Pasó") | E33: =COUNTIFS(HU_Caso!$A$2:$A$44,A33,HU_Caso!$D$2:$D$44,"Falló")+COUNTIFS(HU_Caso!$A$2:$A$44,A33,HU_Caso!$D$2:$D$44,"Error") | F33: =C33-D33-E33
A34: 212 | B34: HU 2.1.1 Desarrollo de evaluación | C34: =COUNTIF(HU_Caso!$A$2:$A$44,A34) | D34: =COUNTIFS(HU_Caso!$A$2:$A$44,A34,HU_Caso!$D$2:$D$44,"Pasó") | E34: =COUNTIFS(HU_Caso!$A$2:$A$44,A34,HU_Caso!$D$2:$D$44,"Falló")+COUNTIFS(HU_Caso!$A$2:$A$44,A34,HU_Caso!$D$2:$D$44,"Error") | F34: =C34-D34-E34
A35: 218 | B35: HU 2.1.2 Evaluación de un tema especifico | C35: =COUNTIF(HU_Caso!$A$2:$A$44,A35) | D35: =COUNTIFS(HU_Caso!$A$2:$A$44,A35,HU_Caso!$D$2:$D$44,"Pasó") | E35: =COUNTIFS(HU_Caso!$A$2:$A$44,A35,HU_Caso!$D$2:$D$44,"Falló")+COUNTIFS(HU_Caso!$A$2:$A$44,A35,HU_Caso!$D$2:$D$44,"Error") | F35: =C35-D35-E35
A36: 224 | B36: HU 2.1.3 Creación de rubricas | C36: =COUNTIF(HU_Caso!$A$2:$A$44,A36) | D36: =COUNTIFS(HU_Caso!$A$2:$A$44,A36,HU_Caso!$D$2:$D$44,"Pasó") | E36: =COUNTIFS(HU_Caso!$A$2:$A$44,A36,HU_Caso!$D$2:$D$44,"Falló")+COUNTIFS(HU_Caso!$A$2:$A$44,A36,HU_Caso!$D$2:$D$44,"Error") | F36: =C36-D36-E36
A37: 228 | B37: HU 2.2.1 Asignación de categoría | C37: =COUNTIF(HU_Caso!$A$2:$A$44,A37) | D37: =COUNTIFS(HU_Caso!$A$2:$A$44,A37,HU_Caso!$D$2:$D$44,"Pasó") | E37: =COUNTIFS(HU_Caso!$A$2:$A$44,A37,HU_Caso!$D$2:$D$44,"Falló")+COUNTIFS(HU_Caso!$A$2:$A$44,A37,HU_Caso!$D$2:$D$44,"Error") | F37: =C37-D37-E37
A38: 235 | B38: HU 2.2.2 Identificación de debilidades | C38: =COUNTIF(HU_Caso!$A$2:$A$44,A38) | D38: =COUNTIFS(HU_Caso!$A$2:$A$44,A38,HU_Caso!$D$2:$D$44,"Pasó") | E38: =COUNTIFS(HU_Caso!$A$2:$A$44,A38,HU_Caso!$D$2:$D$44,"Falló")+COUNTIFS(HU_Caso!$A$2:$A$44,A38,HU_Caso!$D$2:$D$44,"Error") | F38: =C38-D38-E38
... A52: 320 | B52: HU 4.2.3 Explicación de categorización | C52: =COUNTIF(HU_Caso!$A$2:$A$44,A52) | D52: =COUNTIFS(HU_Caso!$A$2:$A$44,A52,HU_Caso!$D$2:$D$44,"Pasó") | E52: =COUNTIFS(HU_Caso!$A$2:$A$44,A52,HU_Caso!$D$2:$D$44,"Falló")+COUNTIFS(HU_Caso!$A$2:$A$44,A52,HU_Caso!$D$2:$D$44,"Error") | F52: =C52-D52-E52
A54: "Sin ejecutar" incluye los casos clasificados como No automatizable.

Sheet Hallazgos
A1: Hallazgos de las pruebas
A2: Hallazgos obtenidos al ejecutar las pruebas automatizadas de Katalon contra https://itmentorsoft.com (defectos con caso FAILED y diferencias entre el requisito de Azure y la aplicación) (2026-10-23)
A4: ID | B4: Categoría | C4: Severidad | D4: Hallazgo | E4: Detalle | F4: Evidencia | G4: Casos de Azure | H4: Estado | I4: Recomendación
A5: D-01 | B5: Seguridad | C5: Alta | D5: El token de acceso (JWT) vence a los 60 minutos y no a los 15 exigidos | E5: Tras un login completo con OTP, el claim exp del JWT de acceso queda 3597 s después del inicio de sesión, para Estudiante y Docente. La cookie access_token sí es HttpOnly y Secure y la redirección por rol es correcta. | F5: TC07: bitácora 'vigencia restante del token: 3597 s (esperado ≤ 900 s)'; capturas ESTUDIANTE_bienvenida y DOCENTE_bienvenida. | G5: 485 | H5: Confirmado en ejecución: TC07 FAILED. | I5: Configurar la vigencia del token de acceso en 15 minutos y renovarlo con el refresh token.
A6: D-02 | B6: Seguridad | C6: Alta | D6: El enlace de recuperación de contraseña sigue siendo válido después de 5 minutos | E6: Un enlace real de recuperación usado 357 s después de emitido permitió cambiar la contraseña ('Contraseña actualizada'). La interfaz y Azure indican 5 minutos de vigencia. | F6: TC09: bitácora 'Enlace real emitido a las 13:53:03 y usado a las 13:59:00 (357 s después de emitido)'; captura 04_enlace_real_vencido. | G6: 486, 488 | H6: Confirmado en ejecución: TC09 FAILED. Se envió la contraseña actual, por lo que no cambió. | I6: Expirar el token de recuperación a los 5 minutos en el backend y rechazarlo después.
A7: D-03 | B7: Funcional | C7: Media | D7: Las evaluaciones descartadas quedan registradas como realizadas | E7: Al descartar una evaluación en curso, el sistema la guarda con nota 0.0 y 'Sin clasificar'. Infla 'Evaluaciones realizadas', baja el promedio y altera la comparación con la evaluación anterior. | F7: TC11: el historial de la API pasó de 4 a 6 evaluaciones tras iniciar y descartar dos; captura 05_historial_tras_descartar. | G7: 422, 434 | H7: Confirmado en ejecución: TC11 FAILED. | I7: Eliminar (o no persistir como realizada) la evaluación al descartarla y excluirla de las estadísticas.
A8: D-04 | B8: Funcional | C8: Baja | D8: El correo de recuperación informa 30 minutos de vigencia y la pantalla 5 | E8: El correo 'Solicitud de recuperación de contraseña' dice 'El enlace expirará en 30 minutos', mientras la pantalla de recuperación y Azure indican 5 minutos. | F8: Correo recibido en USUARIO_ESTUDIANTE tras ejecutar TC08 (2026-10-23 13:46 y 13:53). | G8: 486 | H8: Verificado en el correo recibido. | I8: Unificar el texto del correo con la vigencia real (5 minutos).
A9: O-01 | B9: Requisito | C9: Baja | D9: Sin mensaje de autorización al negar el acceso por rol | E9: Al Estudiante se le niega el banco de preguntas (API 403 y redirección a /login) pero no se muestra un mensaje de autorización. | F9: TC02: advertencia en el log de Katalon. | G9: 466 | H9: Advertencia (caso PASSED). | I9: Mostrar un mensaje de acceso no autorizado antes de redirigir.
A10: O-02 | B10: Requisito | C10: Baja | D10: La evaluación permite retroceder y saltar entre preguntas | E10: La interfaz ofrece 'Anterior' y el panel de preguntas; Azure dice 'sin permitir saltar ni retroceder'. | F10: TC03: advertencia en el log de Katalon. | G10: 434 | H10: Advertencia (caso PASSED). | I10: Confirmar con producto el comportamiento vigente y actualizar el requisito o la interfaz.
A11: O-03 | B11: Seguridad | C11: Baja | D11: Copia del JWT en sessionStorage | E11: Además de la cookie HttpOnly, el frontend guarda el JWT en sessionStorage ('auth_token'), accesible desde JavaScript. | F11: TC07: advertencia en el log de Katalon. | G11: 485 | H11: Advertencia. | I11: Usar solo la cookie HttpOnly para el token de acceso.
A12: O-04 | B12: Requisito | C12: Baja | D12: El banco de preguntas pagina de a 10 y no de a 20 | E12: La tabla muestra 10 preguntas por página (6 páginas para 60 preguntas); Azure exige 20. Las vistas filtradas muestran todos los resultados sin paginar. | F12: TC20: bitácora 'Banco: 60 preguntas, 10 filas en la página 1, 6 páginas'. | G12: 468 | H12: Advertencia (caso PASSED). | I12: Ajustar el tamaño de página a 20 o actualizar el requisito.
A13: O-05 | B13: Requisito | C13: Baja | D13: Funciones de reportes descritas en Azure que la interfaz no ofrece | E13: No hay filtro por rango de fechas (#476), no se resaltan los recursos con promedio < 3.5 (#440), no existe el consolidado de 'debilidad común' por tema (#444) ni la severidad alta/media de debilidades (#451). | F13: TC17, TC18 y TC13: advertencias en el log de Katalon. | G13: 476, 440, 444, 451 | H13: Advertencia (casos PASSED). | I13: Priorizar con producto o actualizar los criterios de aceptación.
A14: O-06 | B14: Requisito | C14: Baja | D14: Funciones de ruta de aprendizaje descritas en Azure que no existen | E14: Al finalizar un recurso no se ofrece la evaluación de seguimiento de 10 preguntas (#461) y la aplicación no registra intereses del estudiante (#446). | F14: TC14: advertencias en el log de Katalon. | G14: 461, 446 | H14: Advertencia (caso PASSED). | I14: Priorizar con producto o actualizar los criterios de aceptación.
A15: O-07 | B15: Requisito | C15: Baja | D15: Texto del mensaje genérico del login | E15: El mensaje es 'Correo o contraseña incorrectos.'; Azure indica 'Usuario o contraseña incorrectas'. Es genérico y no revela qué dato falló. | F15: TC04: advertencia en el log de Katalon. | G15: 483 | H15: Advertencia (caso PASSED). | I15: Alinear el texto con el requisito.

Sheet Detalle
A1: ID Azure | B1: Título | C1: HU | D1: Responsable | E1: Tipo | F1: Suite | G1: Caso Katalon | H1: Resultado | I1: Duración (s) | J1: Fecha ejecución | K1: Fuente del resultado | L1: Mensaje / observación | M1: Nota | N1: Hallazgos
A2: 418 | B2: Verificar que se genera un reporte dada una categoria | C2: 241 - HU 2.2.3 Reportes por categoría | D2: Yesid Alexander García López | E2: Automatizado | F2: TS_TC17 | G2: TC17_AZ502_AZ476_AZ455_Reportes_graficos_y_filtro_por_nivel | H2: Pasó | I2: 47.8 | J2: 2026-10-23 14:03:42 | K2: Katalon (TS_TC17)
A3: 422 | B3: Validar el ingreso al módulo de realización de la evaluación inicial | C3: 212 - HU 2.1.1 Desarrollo de evaluación | D3: Carlos Hernando Franco Idarraga | E3: Automatizado | F3: TS_TC11 | G3: TC11_AZ422_Ingreso_al_modulo_de_evaluacion_inicial | H3: Falló | I3: 55.8 | J3: 2026-10-23 14:32:20 | K3: Katalon (TS_TC11) | L3: Test Cases/TC11_AZ422_Ingreso_al_modulo_de_evaluacion_inicial FAILED. | N3: D-03
A4: 426 | B4: Caso de prueba: CP-4.1.1 – Visualización y actualización del progreso de aprendizaje | C4: 291 - HU 4.1.1 Progreso de aprendizaje | D4: Ivan Dario Valencia Correa | E4: Automatizado parcial | F4: TS_TC13 | G4: TC13_AZ426_AZ451_AZ475_Progreso_perfil_y_categoria_del_estudiante | H4: Pasó | I4: 34.6 | J4: 2026-10-23 14:26:17 | K4: Katalon (TS_TC13) | M4: Parcial: vista Mi progreso y avance de la ruta.
A5: 430 | B5: Verificar registro y actualización de contenido académico | C5: 246 - HU 3.1.1 Registro de contenido acádemico | D5: Edison Estival Restrepo Ospina | E5: Automatizado parcial | F5: TS_TC19 | G5: TC19_AZ430_Gestion_de_recursos_validaciones_y_consulta | H5: Pasó | I5: 61.9 | J5: 2026-10-23 14:10:04 | K5: Katalon (TS_TC19) | M5: Parcial: no se guardan recursos para no alterar el catálogo compartido.
A6: 434 | B6: Validar interacción de preguntas de la evaluación inicial | C6: 212 - HU 2.1.1 Desarrollo de evaluación | D6: Carlos Hernando Franco Idarraga | E6: Automatizado | F6: TS_TC03 | G6: TC03_HU211_Evaluacion_inicial_secuencial_y_persistencia_de_respuestas | H6: Pasó | I6: 44.9 | J6: 2026-10-23 14:37:13 | K6: Katalon (TS_TC03) | N6: D-03, O-02
A7: 435 | B7: Garantizar finalización de evaluación inicial | C7: 212 - HU 2.1.1 Desarrollo de evaluación | D7: Carlos Hernando Franco Idarraga | E7: Automatizado | F7: TS_TC12 | G7: TC12_AZ435_AZ457_Finalizacion_y_retroalimentacion_de_la_evaluacion | H7: Pasó | I7: 122.5 | J7: 2026-10-23 14:16:40 | K7: Katalon (TS_TC12)
A8: 436 | B8: Verificar generación y actualización de ruta de aprendizaje personalizada | C8: 251 - HU 3.1.2 Ruta de aprendizaje | D8: Edison Estival Restrepo Ospina | E8: Automatizado parcial | F8: TS_TC14 | G8: TC14_AZ436_AZ446_AZ461_Ruta_de_aprendizaje_y_recomendaciones | H8: Pasó | I8: 56.2 | J8: 2026-10-23 14:27:31 | K8: Katalon (TS_TC14) | M8: Parcial: la notificación al administrador no es observable.
A9: 438 | B9: Verificar actualización y desactivación de recursos académicos | C9: 257 - HU 3.1.3 Actualizar recursos acádemicos | D9: Edison Estival Restrepo Ospina | E9: No automatizable | H9: No automatizable | K9: Clasificación del inventario | M9: Requiere rol Administrador (no hay cuenta). La denegación a otros roles se cubre en TC10.
A10: 440 | B10: Verificar generación de reportes de contenido académico | C10: 262 - HU 3.1.4 Reportes de contenido acádemico | D10: Edison Estival Restrepo Ospina | E10: Automatizado parcial | F10: TS_TC18 | G10: TC18_AZ440_AZ444_Reportes_de_recursos_y_banco_de_preguntas | H10: Pasó | I10: 89.3 | J10: 2026-10-23 14:04:56 | K10: Katalon (TS_TC18) | M10: Parcial: no se resaltan promedios < 3.5 (advertencia). | N10: O-05
A11: 442 | B11: Verificar actualización de rutas de aprendizaje | C11: 268 - HU 3.2.1 Actualizar rutas de aprendizaje | D11: Edison Estival Restrepo Ospina | E11: No automatizable | H11: No automatizable | K11: Clasificación del inventario | M11: La aplicación no ofrece al docente un módulo de rutas: se generan automáticamente.
A12: 444 | B12: Verificar generación de reportes de debilidades por estudiant | C12: 274 - HU 3.2.2 Reportes por estudiante | D12: Edison Estival Restrepo Ospina | E12: Automatizado parcial | F12: TS_TC18 | G12: TC18_AZ440_AZ444_Reportes_de_recursos_y_banco_de_preguntas | H12: Pasó | I12: 89.3 | J12: 2026-10-23 14:04:56 | K12: Katalon (TS_TC18) | M12: Parcial: no existe el consolidado de "debilidad común" (advertencia). | N12: O-05
A13: 446 | B13: Verificar recepción de ruta de aprendizaje personalizada | C13: 279 - HU 3.2.3 Recepción de ruta de aprendizaje personalizada | D13: Edison Estival Restrepo Ospina | E13: Automatizado parcial | F13: TS_TC14 | G13: TC14_AZ436_AZ446_AZ461_Ruta_de_aprendizaje_y_recomendaciones | H13: Pasó | I13: 56.2 | J13: 2026-10-23 14:27:31 | K13: Katalon (TS_TC14) | M13: Parcial: la aplicación no registra intereses del estudiante. | N13: O-06
A14: 448 | B14: Verificar calificación de recursos recomendados | C14: 285 - HU 3.2.4 Dar retrospectiva sobre contenido acádemico | D14: Edison Estival Restrepo Ospina | E14: Automatizado | F14: TS_TC15 | G14: TC15_AZ448_Calificacion_de_recursos_recomendados | H14: Pasó | I14: 49.3 | J14: 2026-10-23 14:30:36 | K14: Katalon (TS_TC15)
A15: 450 | B15: Verificar acceso autorizado a reportes por estudiante | C15: 274 - HU 3.2.2 Reportes por estudiante | D15: Edison Estival Restrepo Ospina | E15: Automatizado | F15: TS_TC16 | G15: TC16_AZ450_AZ500_Acceso_por_rol_a_reportes_y_datos_consolidados | H15: Pasó | I15: 46.8 | J15: 2026-10-23 14:02:30 | K15: Katalon (TS_TC16)
A16: 451 | B16: Caso de prueba: CP-4.2.2 – Identificación, clasificación y actualización de debilidades | C16: 314 - HU 4.2.2 Visualización de debilidades | D16: Ivan Dario Valencia Correa | E16: Automatizado parcial | F16: TS_TC13 | G16: TC13_AZ426_AZ451_AZ475_Progreso_perfil_y_categoria_del_estudiante | H16: Pasó | I16: 34.6 | J16: 2026-10-23 14:26:17 | K16: Katalon (TS_TC13) | M16: Parcial: no se muestra la severidad alta/media. | N16: O-05
A17: 455 | B17: Caso de prueba: CP-4.1.3 – Consulta y filtrado del progreso de estudiantes desde el dashboard docente | C17: 303 - HU 4.1.3 Progreso de estudiantes desde Docente | D17: Ivan Dario Valencia Correa | E17: Automatizado | F17: TS_TC17 | G17: TC17_AZ502_AZ476_AZ455_Reportes_graficos_y_filtro_por_nivel | H17: Pasó | I17: 47.8 | J17: 2026-10-23 14:03:42 | K17: Katalon (TS_TC17)
A18: 457 | B18: Caso de prueba: CP-4.2.1 – Generación y consulta de retroalimentación de una evaluación | C18: 308 - HU 4.2.1 Feedback por evaluación | D18: Ivan Dario Valencia Correa | E18: Automatizado | F18: TS_TC12 | G18: TC12_AZ435_AZ457_Finalizacion_y_retroalimentacion_de_la_evaluacion | H18: Pasó | I18: 122.5 | J18: 2026-10-23 14:16:40 | K18: Katalon (TS_TC12)
A19: 459 | B19: Caso de prueba: CP-4.2.3 – Generación y visualización de la explicación de categorización | C19: 320 - HU 4.2.3 Explicación de categorización | D19: Ivan Dario Valencia Correa | E19: Automatizado parcial | F19: TS_TC13 | G19: TC13_AZ426_AZ451_AZ475_Progreso_perfil_y_categoria_del_estudiante | H19: Pasó | I19: 34.6 | J19: 2026-10-23 14:26:17 | K19: Katalon (TS_TC13) | M19: Parcial: las variables del modelo no son observables.
A20: 461 | B20: Validar confirmación de recurso finalizado y selección exacta de 10 preguntas aleatorias | C20: 218 - HU 2.1.2 Evaluación de un tema especifico | D20: Carlos Hernando Franco Idarraga | E20: Automatizado parcial | F20: TS_TC14 | G20: TC14_AZ436_AZ446_AZ461_Ruta_de_aprendizaje_y_recomendaciones | H20: Pasó | I20: 56.2 | J20: 2026-10-23 14:27:31 | K20: Katalon (TS_TC14) | M20: Parcial: no existe la evaluación de seguimiento de 10 preguntas. | N20: O-06
A21: 465 | B21: Verificar recalificación de nivel y visualización de gráfica comparativa de progreso histórico | C21: 218 - HU 2.1.2 Evaluación de un tema especifico | D21: Carlos Hernando Franco Idarraga | E21: Automatizado parcial | F21: TS_TC13 | G21: TC13_AZ426_AZ451_AZ475_Progreso_perfil_y_categoria_del_estudiante | H21: Pasó | I21: 34.6 | J21: 2026-10-23 14:26:17 | K21: Katalon (TS_TC13) | M21: Parcial: la recalificación requiere varias evaluaciones de seguimiento.
A22: 466 | B22: Verificar restricción de acceso al módulo de administración de evaluaciones según el rol del usuario | C22: 224 - HU 2.1.3 Creación de rubricas | D22: Carlos Hernando Franco Idarraga | E22: Automatizado | F22: TS_TC02 | G22: TC02_HU213_Restriccion_acceso_por_rol_a_administracion_de_evaluaciones | H22: Pasó | I22: 50.8 | J22: 2026-10-23 14:35:59 | K22: Katalon (TS_TC02) | N22: O-01
A23: 468 | B23: Validar paginación exacta de 20 preguntas por tema y persistencia de operaciones CRUD en cuestionarios | C23: 224 - HU 2.1.3 Creación de rubricas | D23: Carlos Hernando Franco Idarraga | E23: Automatizado parcial | F23: TS_TC20 | G23: TC20_AZ468_Banco_de_preguntas_paginacion_filtros_y_versiones | H23: Pasó | I23: 75.6 | J23: 2026-10-23 14:11:39 | K23: Katalon (TS_TC20) | M23: Parcial: pagina de a 10 (Azure: 20); no se crean ni editan preguntas. | N23: O-04
A24: 469 | B24: Validar la generación de JSON y asignación de categoría única por el modelo de ML | C24: 228 - HU 2.2.1 Asignación de categoría | D24: Carlos Hernando Franco Idarraga | E24: No automatizable | H24: No automatizable | K24: Clasificación del inventario | M24: Interno del modelo de ML. Evidencia indirecta en TC12/TC13 (un único nivel asignado).
A25: 471 | B25: Verificar la resiliencia del sistema ante fallos de ejecución del modelo de ML o fallos de base de datos | C25: 228 - HU 2.2.1 Asignación de categoría | D25: Carlos Hernando Franco Idarraga | E25: No automatizable | H25: No automatizable | K25: Clasificación del inventario | M25: Requiere inyectar fallos en la infraestructura del entorno.
A26: 472 | B26: Validar actualización de categoría, conservación de histórico de versiones y notificación al perfil | C26: 228 - HU 2.2.1 Asignación de categoría | D26: Carlos Hernando Franco Idarraga | E26: No automatizable | H26: No automatizable | K26: Clasificación del inventario | M26: Requiere varias reclasificaciones y acceso al histórico del modelo.
A27: 473 | B27: Validar regla de al menos 3 objetivos por categoría y alerta de objetivos no asignados en CRUD | C27: 235 - HU 2.2.2 Identificación de debilidades | D27: Carlos Hernando Franco Idarraga | E27: No automatizable | H27: No automatizable | K27: Clasificación del inventario | M27: Configuración de categorías y objetivos reservada al Administrador.
A28: 475 | B28: Verificar despliegue de objetivos según la categoría asignada o mensaje de evaluación pendiente | C28: 235 - HU 2.2.2 Identificación de debilidades | D28: Carlos Hernando Franco Idarraga | E28: Automatizado | F28: TS_TC13 | G28: TC13_AZ426_AZ451_AZ475_Progreso_perfil_y_categoria_del_estudiante | H28: Pasó | I28: 34.6 | J28: 2026-10-23 14:26:17 | K28: Katalon (TS_TC13)
A29: 476 | B29: Validar consolidación de estudiantes por categoría, cálculo de métricas y filtros en dashboard docente | C29: 241 - HU 2.2.3 Reportes por categoría | D29: Carlos Hernando Franco Idarraga | E29: Automatizado | F29: TS_TC17 | G29: TC17_AZ502_AZ476_AZ455_Reportes_graficos_y_filtro_por_nivel | H29: Pasó | I29: 47.8 | J29: 2026-10-23 14:03:42 | K29: Katalon (TS_TC17) | N29: O-05
A30: 477 | B30: Verificar activación de alerta 'requiere mejora' para categorías con promedio de calificación inferior al 70% | C30: 241 - HU 2.2.3 Reportes por categoría | D30: Carlos Hernando Franco Idarraga | E30: No automatizable | H30: No automatizable | K30: Clasificación del inventario | M30: Alerta dirigida al Administrador; no visible para Docente ni Estudiante.
A31: 478 | B31: Validar limites de longitud y expresiones regulares en campos del formulario de registro | C31: 176 - HU 1.1.1 Registro de usuarios | D31: Carlos Hernando Franco Idarraga | E31: Automatizado | F31: TS_TC05 | G31: TC05_AZ478_Registro_limites_de_longitud_y_formato | H31: Pasó | I31: 59.7 | J31: 2026-10-23 13:43:40 | K31: Katalon (TS_TC05)
A32: 482 | B32: Verificar unicidad de username/email y almacenamiento seguro mediante hash bcrypt/Argon2 | C32: 176 - HU 1.1.1 Registro de usuarios | D32: Carlos Hernando Franco Idarraga | E32: Automatizado parcial | F32: TS_TC06 | G32: TC06_AZ482_Registro_unicidad_de_usuario_y_correo | H32: Pasó | I32: 37 | J32: 2026-10-23 13:45:05 | K32: Katalon (TS_TC06) | M32: Parcial: el hash bcrypt/Argon2 no es observable.
A33: 483 | B33: Validar manejo de errores de formato y mensaje genérico ante credenciales incorrectas | C33: 181 - HU 1.1.2 Inicio de sesión | D33: Carlos Hernando Franco Idarraga | E33: Automatizado | F33: TS_TC04 | G33: TC04_AZ483_Login_errores_de_formato_y_mensaje_generico | H33: Pasó | I33: 37.2 | J33: 2026-10-23 13:42:35 | K33: Katalon (TS_TC04) | N33: O-07
A34: 485 | B34: Verificar la emisión de cookie JWT HttpOnly/Secure con expiración de 15 minutos y redirección según rol | C34: 181 - HU 1.1.2 Inicio de sesión | D34: Carlos Hernando Franco Idarraga | E34: Automatizado | F34: TS_TC07 | G34: TC07_AZ485_Login_exitoso_cookie_segura_y_redireccion_por_rol | H34: Falló | I34: 129 | J34: 2026-10-23 13:59:40 | K34: Katalon (TS_TC07) | L34: Test Cases/TC07_AZ485_Login_exitoso_cookie_segura_y_redireccion_por_rol FAILED. | N34: D-01, O-03
A35: 486 | B35: Validar mensaje de privacidad genérico y vigencia límite de 5 minutos en el token de recuperación | C35: 186 - HU 1.1.3 Reestablecer contraseña | D35: Carlos Hernando Franco Idarraga | E35: Automatizado | F35: TS_TC08 | G35: TC08_AZ486_Recuperacion_mensaje_generico_y_vigencia | H35: Pasó | I35: 33.6 | J35: 2026-10-23 13:52:16 | K35: Katalon (TS_TC08) | N35: D-02, D-04
A36: 488 | B36: Verificar validación de token vencido, requisitos de contraseña segura y revocación de sesiones previas | C36: 186 - HU 1.1.3 Reestablecer contraseña | D36: Carlos Hernando Franco Idarraga | E36: Automatizado | F36: TS_TC09 | G36: TC09_AZ488_Restablecimiento_enlace_invalido_y_complejidad | H36: Falló | I36: 276.5 | J36: 2026-10-23 13:54:23 | K36: Katalon (TS_TC09) | L36: Test Cases/TC09_AZ488_Restablecimiento_enlace_invalido_y_complejidad FAILED. | N36: D-02
A37: 489 | B37: Validar edición de permisos por rol y restricción de acceso según permisos asignados | C37: 193 - HU 1.2.1 Asignación de roles | D37: Carlos Hernando Franco Idarraga | E37: Automatizado parcial | F37: TS_TC10 | G37: TC10_AZ494_Middleware_401_y_403_segun_token_y_rol | H37: Pasó | I37: 33.4 | J37: 2026-10-23 14:14:32 | K37: Katalon (TS_TC10) | M37: Parcial: solo la restricción de acceso; la edición de permisos requiere Administrador.
A38: 493 | B38: Verificar bloqueo de eliminación de roles asociados a uno o más usuarios activos | C38: 193 - HU 1.2.1 Asignación de roles | D38: Carlos Hernando Franco Idarraga | E38: No automatizable | H38: No automatizable | K38: Clasificación del inventario | M38: Gestión de roles reservada al Administrador.
A39: 494 | B39: Validar interceptación de Middleware retornando HTTP 401 y HTTP 403 según token y permisos | C39: 198 - HU 1.2.2 Acceso y privacidad en datos | D39: Carlos Hernando Franco Idarraga | E39: Automatizado | F39: TS_TC10 | G39: TC10_AZ494_Middleware_401_y_403_segun_token_y_rol | H39: Pasó | I39: 33.4 | J39: 2026-10-23 14:14:32 | K39: Katalon (TS_TC10)
A40: 496 | B40: Verificar aislamiento estricto de información académica y enmascaramiento con HTTP 404 | C40: 198 - HU 1.2.2 Acceso y privacidad en datos | D40: Carlos Hernando Franco Idarraga | E40: Automatizado | F40: TS_TC01 | G40: TC01_HU122_Aislamiento_datos_academicos_entre_estudiantes | H40: Pasó | I40: 50.8 | J40: 2026-10-23 14:34:36 | K40: Katalon (TS_TC01)
...

Sheet HU_Caso
A1: HU | B1: Título HU | C1: ID caso | D1: Resultado
A2: 241 | B2: HU 2.2.3 Reportes por categoría | C2: 418 | D2: =INDEX(Detalle!$H$2:$H$44,MATCH(C2,Detalle!$A$2:$A$44,0))
A3: 212 | B3: HU 2.1.1 Desarrollo de evaluación | C3: 422 | D3: =INDEX(Detalle!$H$2:$H$44,MATCH(C3,Detalle!$A$2:$A$44,0))
A4: 291 | B4: HU 4.1.1 Progreso de aprendizaje | C4: 426 | D4: =INDEX(Detalle!$H$2:$H$44,MATCH(C4,Detalle!$A$2:$A$44,0))
A5: 246 | B5: HU 3.1.1 Registro de contenido acádemico | C5: 430 | D5: =INDEX(Detalle!$H$2:$H$44,MATCH(C5,Detalle!$A$2:$A$44,0))
A6: 212 | B6: HU 2.1.1 Desarrollo de evaluación | C6: 434 | D6: =INDEX(Detalle!$H$2:$H$44,MATCH(C6,Detalle!$A$2:$A$44,0))
A7: 212 | B7: HU 2.1.1 Desarrollo de evaluación | C7: 435 | D7: =INDEX(Detalle!$H$2:$H$44,MATCH(C7,Detalle!$A$2:$A$44,0))
A8: 251 | B8: HU 3.1.2 Ruta de aprendizaje | C8: 436 | D8: =INDEX(Detalle!$H$2:$H$44,MATCH(C8,Detalle!$A$2:$A$44,0))
A9: 257 | B9: HU 3.1.3 Actualizar recursos acádemicos | C9: 438 | D9: =INDEX(Detalle!$H$2:$H$44,MATCH(C9,Detalle!$A$2:$A$44,0))
A10: 262 | B10: HU 3.1.4 Reportes de contenido acádemico | C10: 440 | D10: =INDEX(Detalle!$H$2:$H$44,MATCH(C10,Detalle!$A$2:$A$44,0))
A11: 268 | B11: HU 3.2.1 Actualizar rutas de aprendizaje | C11: 442 | D11: =INDEX(Detalle!$H$2:$H$44,MATCH(C11,Detalle!$A$2:$A$44,0))
A12: 274 | B12: HU 3.2.2 Reportes por estudiante | C12: 444 | D12: =INDEX(Detalle!$H$2:$H$44,MATCH(C12,Detalle!$A$2:$A$44,0))
A13: 279 | B13: HU 3.2.3 Recepción de ruta de aprendizaje personalizada | C13: 446 | D13: =INDEX(Detalle!$H$2:$H$44,MATCH(C13,Detalle!$A$2:$A$44,0))
... A44: 207 | B44: HU 1.2.4 Reportes de estudiantes | C44: 502 | D44: =INDEX(Detalle!$H$2:$H$44,MATCH(C44,Detalle!$A$2:$A$44,0))

Sheet Casos_Katalon
A1: Caso | B1: Test case Katalon | C1: Casos Azure | D1: Resultado | E1: Fecha ejecución | F1: Duración (s) | G1: Ejecuciones | H1: Mensaje | I1: Advertencias | J1: Hallazgos | K1: Reporte de la prueba
A2: TC01 | B2: TC01_HU122_Aislamiento_datos_academicos_entre_estudiantes | C2: #496 | D2: Pasó | E2: 2026-10-23 14:34:36 | F2: 50.8 | G2: 2 | K2: Por_prueba/TC01_HU122_Aislamiento_datos_academicos_entre_estudiantes.xlsx
A3: TC02 | B3: TC02_HU213_Restriccion_acceso_por_rol_a_administracion_de_evaluaciones | C3: #466 | D3: Pasó | E3: 2026-10-23 14:35:59 | F3: 50.8 | G3: 2 | I3: [TC02] Observación HU 2.1.3 CA1: no se verificó el mensaje de autorización (columna mensaje_denegacion_esperado vacía). La aplicación redirige sin mensaje; URL final: https://itmentorsoft.com/login. | J3: O-01 | K3: Por_prueba/TC02_HU213_Restriccion_acceso_por_rol_a_administracion_de_evaluaciones.xlsx
A4: TC03 | B4: TC03_HU211_Evaluacion_inicial_secuencial_y_persistencia_de_respuestas | C4: #434 | D4: Pasó | E4: 2026-10-23 14:37:13 | F4: 44.9 | G4: 4 | I4: [TC03] Observación HU 2.1.1 CA2: la interfaz ofrece 'Anterior' y el panel 'Tus preguntas' para saltar entre preguntas. La redacción de Azure dice 'sin permitir saltar entre preguntas ni retroceder'; confirmar con producto cuál es el comportamiento vigente. | J4: D-03, O-02 | K4: Por_prueba/TC03_HU211_Evaluacion_inicial_secuencial_y_persistencia_de_respuestas.xlsx
A5: TC04 | B5: TC04_AZ483_Login_errores_de_formato_y_mensaje_generico | C5: #483 | D5: Pasó | E5: 2026-10-23 13:42:35 | F5: 37.2 | G5: 4 | I5: [TC04] Observación #483: el mensaje genérico es 'No se pudo iniciar sesión | Correo o contraseña incorrectos.'; Azure indica el texto 'Usuario o contraseña incorrectas'. Es genérico y no revela el dato, pero el texto difiere. | J5: O-07 | K5: Por_prueba/TC04_AZ483_Login_errores_de_formato_y_mensaje_generico.xlsx
A6: TC05 | B6: TC05_AZ478_Registro_limites_de_longitud_y_formato | C6: #478 | D6: Pasó | E6: 2026-10-23 13:43:40 | F6: 59.7 | G6: 1 | K6: Por_prueba/TC05_AZ478_Registro_limites_de_longitud_y_formato.xlsx
A7: TC06 | B7: TC06_AZ482_Registro_unicidad_de_usuario_y_correo | C7: #482 | D7: Pasó | E7: 2026-10-23 13:45:05 | F7: 37 | G7: 1 | K7: Por_prueba/TC06_AZ482_Registro_unicidad_de_usuario_y_correo.xlsx
A8: TC07 | B8: TC07_AZ485_Login_exitoso_cookie_segura_y_redireccion_por_rol | C8: #485 | D8: Falló | E8: 2026-10-23 13:59:40 | F8: 129 | G8: 1 | H8: Test Cases/TC07_AZ485_Login_exitoso_cookie_segura_y_redireccion_por_rol FAILED. | I8: [TC07] Observación de seguridad #485: además de la cookie HttpOnly, el frontend guarda una copia del JWT en sessionStorage ('auth_token'), accesible desde JavaScript. | J8: D-01, O-03 | K8: Por_prueba/TC07_AZ485_Login_exitoso_cookie_segura_y_redireccion_por_rol.xlsx
A9: TC08 | B9: TC08_AZ486_Recuperacion_mensaje_generico_y_vigencia | C9: #486 | D9: Pasó | E9: 2026-10-23 13:52:16 | F9: 33.6 | G9: 2 | J9: D-02, D-04 | K9: Por_prueba/TC08_AZ486_Recuperacion_mensaje_generico_y_vigencia.xlsx
A10: TC09 | B10: TC09_AZ488_Restablecimiento_enlace_invalido_y_complejidad | C10: #488 | D10: Falló | E10: 2026-10-23 13:54:23 | F10: 276.5 | G10: 2 | H10: Test Cases/TC09_AZ488_Restablecimiento_enlace_invalido_y_complejidad FAILED. | J10: D-02 | K10: Por_prueba/TC09_AZ488_Restablecimiento_enlace_invalido_y_complejidad.xlsx
A11: TC10 | B11: TC10_AZ494_Middleware_401_y_403_segun_token_y_rol | C11: #489, #494 | D11: Pasó | E11: 2026-10-23 14:14:32 | F11: 33.4 | G11: 2 | K11: Por_prueba/TC10_AZ494_Middleware_401_y_403_segun_token_y_rol.xlsx
A12: TC11 | B12: TC11_AZ422_Ingreso_al_modulo_de_evaluacion_inicial | C12: #422 | D12: Falló | E12: 2026-10-23 14:32:20 | F12: 55.8 | G12: 2 | H12: Test Cases/TC11_AZ422_Ingreso_al_modulo_de_evaluacion_inicial FAILED. | J12: D-03 | K12: Por_prueba/TC11_AZ422_Ingreso_al_modulo_de_evaluacion_inicial.xlsx
A13: TC12 | B13: TC12_AZ435_AZ457_Finalizacion_y_retroalimentacion_de_la_evaluacion | C13: #435, #457 | D13: Pasó | E13: 2026-10-23 14:16:40 | F13: 122.5 | G13: 1 | K13: Por_prueba/TC12_AZ435_AZ457_Finalizacion_y_retroalimentacion_de_la_evaluacion.xlsx
A14: TC13 | B14: TC13_AZ426_AZ451_AZ475_Progreso_perfil_y_categoria_del_estudiante | C14: #426, #451, #459, #465, #475 | D14: Pasó | E14: 2026-10-23 14:26:17 | F14: 34.6 | G14: 1 | I14: [TC13] Observación #451: la interfaz muestra el porcentaje por tema, pero no clasifica las debilidades por severidad (alta < 50 %, media 50-69 %). | J14: O-05 | K14: Por_prueba/TC13_AZ426_AZ451_AZ475_Progreso_perfil_y_categoria_del_estudiante.xlsx
A15: TC14 | B15: TC14_AZ436_AZ446_AZ461_Ruta_de_aprendizaje_y_recomendaciones | C15: #436, #446, #461 | D15: Pasó | E15: 2026-10-23 14:27:31 | F15: 56.2 | G15: 1 | I15: [TC14] Observación #461: al finalizar un recurso la aplicación no ofrece la evaluación de seguimiento de 10 preguntas aleatorias descrita en Azure. [TC14] Observación #446: la aplicación no registra intereses del estudiante; las recomendaciones se basan solo en las debilidades. | J15: O-06 | K15: Por_prueba/TC14_AZ436_AZ446_AZ461_Ruta_de_aprendizaje_y_recomendaciones.xlsx
A16: TC15 | B16: TC15_AZ448_Calificacion_de_recursos_recomendados | C16: #448 | D16: Pasó | E16: 2026-10-23 14:30:36 | F16: 49.3 | G16: 2 | K16: Por_prueba/TC15_AZ448_Calificacion_de_recursos_recomendados.xlsx
A17: TC16 | B17: TC16_AZ450_AZ500_Acceso_por_rol_a_reportes_y_datos_consolidados | C17: #450, #500 | D17: Pasó | E17: 2026-10-23 14:02:30 | F17: 46.8 | G17: 1 | K17: Por_prueba/TC16_AZ450_AZ500_Acceso_por_rol_a_reportes_y_datos_consolidados.xlsx
A18: TC17 | B18: TC17_AZ502_AZ476_AZ455_Reportes_graficos_y_filtro_por_nivel | C18: #418, #455, #476, #502 | D18: Pasó | E18: 2026-10-23 14:03:42 | F18: 47.8 | G18: 1 | I18: [TC17] Observación #476: el dashboard docente no ofrece filtro por rango de fechas para la consolidación por categoría. [TC17] Observación #455/#502: no se verificó la vista 'sin datos disponibles' porque el entorno tiene estudiantes clasificados en todos los niveles. | J18: O-05 | K18: Por_prueba/TC17_AZ502_AZ476_AZ455_Reportes_graficos_y_filtro_por_nivel.xlsx
A19: TC18 | B19: TC18_AZ440_AZ444_Reportes_de_recursos_y_banco_de_preguntas | C19: #440, #444 | D19: Pasó | E19: 2026-10-23 14:04:56 | F19: 89.3 | G19: 1 | I19: [TC18] Observación #440: la interfaz no resalta los recursos con promedio menor a 3.5 ni muestra el porcentaje de recursos con baja valoración. [TC18] Observación #444: no existe un reporte consolidado de debilidades por tema (promedio < 70 % y 'debilidad común' con ≥ 30 % de estudiantes); el docente solo ve el progreso por tema de cada estudiante. | J19: O-05 | K19: Por_prueba/TC18_AZ440_AZ444_Reportes_de_recursos_y_banco_de_preguntas.xlsx
A20: TC19 | B20: TC19_AZ430_Gestion_de_recursos_validaciones_y_consulta | C20: #430 | D20: Pasó | E20: 2026-10-23 14:10:04 | F20: 61.9 | G20: 2 | K20: Por_prueba/TC19_AZ430_Gestion_de_recursos_validaciones_y_consulta.xlsx
A21: TC20 | B21: TC20_AZ468_Banco_de_preguntas_paginacion_filtros_y_versiones | C21: #468, #499 | D21: Pasó | E21: 2026-10-23 14:11:39 | F21: 75.6 | G21: 1 | I21: [TC20] Observación #468: el banco pagina de a 10 preguntas; Azure exige exactamente 20 por página. [TC20] Alcance #468: la persistencia del CRUD (crear, editar, desactivar) no se automatizó para no alterar el banco que usan las evaluaciones reales. | J21: O-04 | K21: Por_prueba/TC20_AZ468_Banco_de_preguntas_paginacion_filtros_y_versiones.xlsx

Sheet Ejecuciones
A1: Fecha | B1: Suite | C1: Caso | D1: Test case Katalon | E1: Resultado | F1: Duración (s) | G1: Mensaje | H1: Reporte
A2: 2026-10-23 14:37:13 | B2: TS_TC03 | C2: TC03 | D2: TC03_HU211_Evaluacion_inicial_secuencial_y_persistencia_de_respuestas | E2: Pasó | F2: 44.9 | H2: Reports/20261023_143656/TS_TC03/20261023_143656
A3: 2026-10-23 14:35:59 | B3: TS_TC02 | C3: TC02 | D3: TC02_HU213_Restriccion_acceso_por_rol_a_administracion_de_evaluaciones | E3: Pasó | F3: 50.8 | H3: Reports/20261023_143537/TS_TC02/20261023_143537
A4: 2026-10-23 14:34:36 | B4: TS_TC01 | C4: TC01 | D4: TC01_HU122_Aislamiento_datos_academicos_entre_estudiantes | E4: Pasó | F4: 50.8 | H4: Reports/20261023_143352/TS_TC01/20261023_143352
A5: 2026-10-23 14:32:20 | B5: TS_TC11 | C5: TC11 | D5: TC11_AZ422_Ingreso_al_modulo_de_evaluacion_inicial | E5: Falló | F5: 55.8 | G5: Test Cases/TC11_AZ422_Ingreso_al_modulo_de_evaluacion_inicial FAILED. | H5: Reports/20261023_143206/TS_TC11/20261023_143206
A6: 2026-10-23 14:30:36 | B6: TS_TC15 | C6: TC15 | D6: TC15_AZ448_Calificacion_de_recursos_recomendados | E6: Pasó | F6: 49.3 | H6: Reports/20261023_143013/TS_TC15/20261023_143013
A7: 2026-10-23 14:28:55 | B7: TS_TC15 | C7: TC15 | D7: TC15_AZ448_Calificacion_de_recursos_recomendados | E7: Pasó | F7: 39.4 | H7: Reports/20261023_142841/TS_TC15/20261023_142841
A8: 2026-10-23 14:27:31 | B8: TS_TC14 | C8: TC14 | D8: TC14_AZ436_AZ446_AZ461_Ruta_de_aprendizaje_y_recomendaciones | E8: Pasó | F8: 56.2 | H8: Reports/20261023_142719/TS_TC14/20261023_142719
A9: 2026-10-23 14:26:17 | B9: TS_TC13 | C9: TC13 | D9: TC13_AZ426_AZ451_AZ475_Progreso_perfil_y_categoria_del_estudiante | E9: Pasó | F9: 34.6 | H9: Reports/20261023_142600/TS_TC13/20261023_142600
A10: 2026-10-23 14:16:40 | B10: TS_TC12 | C10: TC12 | D10: TC12_AZ435_AZ457_Finalizacion_y_retroalimentacion_de_la_evaluacion | E10: Pasó | F10: 122.5 | H10: Reports/20261023_141628/TS_TC12/20261023_141628
A11: 2026-10-23 14:15:28 | B11: TS_TC11 | C11: TC11 | D11: TC11_AZ422_Ingreso_al_modulo_de_evaluacion_inicial | E11: Pasó | F11: 43 | H11: Reports/20261023_141517/TS_TC11/20261023_141517
A12: 2026-10-23 14:14:32 | B12: TS_TC10 | C12: TC10 | D12: TC10_AZ494_Middleware_401_y_403_segun_token_y_rol | E12: Pasó | F12: 33.4 | H12: Reports/20261023_141422/TS_TC10/20261023_141422
A13: 2026-10-23 14:13:20 | B13: TS_TC10 | C13: TC10 | D13: TC10_AZ494_Middleware_401_y_403_segun_token_y_rol | E13: Falló | F13: 34 | G13: Test Cases/TC10_AZ494_Middleware_401_y_403_segun_token_y_rol FAILED. | H13: Reports/20261023_141309/TS_TC10/20261023_141309
A14: 2026-10-23 14:11:39 | B14: TS_TC20 | C14: TC20 | D14: TC20_AZ468_Banco_de_preguntas_paginacion_filtros_y_versiones | E14: Pasó | F14: 75.6 | H14: Reports/20261023_141128/TS_TC20/20261023_141128
A15: 2026-10-23 14:10:04 | B15: TS_TC19 | C15: TC19 | D15: TC19_AZ430_Gestion_de_recursos_validaciones_y_consulta | E15: Pasó | F15: 61.9 | H15: Reports/20261023_140943/TS_TC19/20261023_140943
A16: 2026-10-23 14:07:09 | B16: TS_TC19 | C16: TC19 | D16: TC19_AZ430_Gestion_de_recursos_validaciones_y_consulta | E16: Falló | F16: 72.2 | G16: Test Cases/TC19_AZ430_Gestion_de_recursos_validaciones_y_consulta FAILED. | H16: Reports/20261023_140645/TS_TC19/20261023_140645
A17: 2026-10-23 14:04:56 | B17: TS_TC18 | C17: TC18 | D17: TC18_AZ440_AZ444_Reportes_de_recursos_y_banco_de_preguntas | E17: Pasó | F17: 89.3 | H17: Reports/20261023_140446/TS_TC18/20261023_140446
A18: 2026-10-23 14:03:42 | B18: TS_TC17 | C18: TC17 | D18: TC17_AZ502_AZ476_AZ455_Reportes_graficos_y_filtro_por_nivel | E18: Pasó | F18: 47.8 | H18: Reports/20261023_140331/TS_TC17/20261023_140331
A19: 2026-10-23 14:02:30 | B19: TS_TC16 | C19: TC16 | D19: TC16_AZ450_AZ500_Acceso_por_rol_a_reportes_y_datos_consolidados | E19: Pasó | F19: 46.8 | H19: Reports/20261023_140216/TS_TC16/20261023_140216
A20: 2026-10-23 13:59:40 | B20: TS_TC07 | C20: TC07 | D20: TC07_AZ485_Login_exitoso_cookie_segura_y_redireccion_por_rol | E20: Falló | F20: 129 | G20: Test Cases/TC07_AZ485_Login_exitoso_cookie_segura_y_redireccion_por_rol FAILED. | H20: Reports/20261023_135930/TS_TC07/20261023_135930
A21: 2026-10-23 13:54:23 | B21: TS_TC09 | C21: TC09 | D21: TC09_AZ488_Restablecimiento_enlace_invalido_y_complejidad | E21: Falló | F21: 276.5 | G21: Test Cases/TC09_AZ488_Restablecimiento_enlace_invalido_y_complejidad FAILED. | H21: Reports/20261023_135414/TS_TC09/20261023_135414
A22: 2026-10-23 13:52:16 | B22: TS_TC08 | C22: TC08 | D22: TC08_AZ486_Recuperacion_mensaje_generico_y_vigencia | E22: Pasó | F22: 33.6 | H22: Reports/20261023_135207/TS_TC08/20261023_135207
A23: 2026-10-23 13:49:31 | B23: TS_TC09 | C23: TC09 | D23: TC09_AZ488_Restablecimiento_enlace_invalido_y_complejidad | E23: Falló | F23: 111.4 | G23: Test Cases/TC09_AZ488_Restablecimiento_enlace_invalido_y_complejidad FAILED. | H23: Reports/20261023_134921/TS_TC09/20261023_134921
A24: 2026-10-23 13:46:12 | B24: TS_TC08 | C24: TC08 | D24: TC08_AZ486_Recuperacion_mensaje_generico_y_vigencia | E24: Pasó | F24: 40.6 | H24: Reports/20261023_134557/TS_TC08/20261023_134557
A25: 2026-10-23 13:45:05 | B25: TS_TC06 | C25: TC06 | D25: TC06_AZ482_Registro_unicidad_de_usuario_y_correo | E25: Pasó | F25: 37 | H25: Reports/20261023_134452/TS_TC06/20261023_134452
A26: 2026-10-23 13:43:40 | B26: TS_TC05 | C26: TC05 | D26: TC05_AZ478_Registro_limites_de_longitud_y_formato | E26: Pasó | F26: 59.7 | H26: Reports/20261023_134325/TS_TC05/20261023_134325
A27: 2026-10-23 13:42:35 | B27: TS_TC04 | C27: TC04 | D27: TC04_AZ483_Login_errores_de_formato_y_mensaje_generico | E27: Pasó | F27: 37.2 | H27: Reports/20261023_134217/TS_TC04/20261023_134217
A28: 2026-10-23 13:41:44 | B28: TS_TC04 | C28: TC04 | D28: TC04_AZ483_Login_errores_de_formato_y_mensaje_generico | E28: Falló | F28: 12.6 | G28: Test Cases/TC04_AZ483_Login_errores_de_formato_y_mensaje_generico FAILED. | H28: Reports/20261023_134134/TS_TC04/20261023_134134
A29: 2026-10-23 13:40:13 | B29: TS_TC04 | C29: TC04 | D29: TC04_AZ483_Login_errores_de_formato_y_mensaje_generico | E29: Pasó | F29: 43.5 | H29: Reports/20261023_133958/TS_TC04/20261023_133958
A30: 2026-10-23 13:37:45 | B30: TS_TC04 | C30: TC04 | D30: TC04_AZ483_Login_errores_de_formato_y_mensaje_generico | E30: Falló | F30: 39.5 | G30: Test Cases/TC04_AZ483_Login_errores_de_formato_y_mensaje_generico FAILED. | H30: Reports/20261023_133729/TS_TC04/20261023_133729
A31: 2026-10-21 21:49:09 | B31: TS_TC02 | C31: TC02 | D31: TC02_HU213_Restriccion_acceso_por_rol_a_administracion_de_evaluaciones | E31: Pasó | F31: 134.5 | H31: Reports/20261021_214853/TS_TC02/20261021_214853
A32: 2026-10-21 21:46:24 | B32: TS_TC01 | C32: TC01 | D32: TC01_HU122_Aislamiento_datos_academicos_entre_estudiantes | E32: Pasó | F32: 121.2 | H32: Reports/20261021_214606/TS_TC01/20261021_214606
A33: 2026-10-21 21:42:35 | B33: TS_TC03 | C33: TC03 | D33: TC03_HU211_Evaluacion_inicial_secuencial_y_persistencia_de_respuestas | E33: Pasó | F33: 91.9 | H33: Reports/20261021_214208/TS_TC03/20261021_214208
A34: 2026-10-21 21:35:04 | B34: TS_TC03 | C34: TC03 | D34: TC03_HU211_Evaluacion_inicial_secuencial_y_persistencia_de_respuestas | E34: Falló | F34: 109.4 | G34: Test Cases/TC03_HU211_Evaluacion_inicial_secuencial_y_persistencia_de_respuestas FAILED. | H34: Reports/20261021_213446/TS_TC03/20261021_213446
A35: 2026-10-21 21:33:55 | B35: TS_TC03 | C35: TC03 | D35: TC03_HU211_Evaluacion_inicial_secuencial_y_persistencia_de_respuestas | E35: Error | F35: 5.3 | G35: Test Cases/TC03_HU211_Evaluacion_inicial_secuencial_y_persistencia_de_respuestas FAILED. | H35: Reports/20261021_213332/TS_TC03/20261021_213333
